[META]
version=2.0
spawnOnBlockType=2,3,12
spawnSunlight=True
spawnDarkness=True
spawnWater=False
spawnLava=False
underFill=True
randomRotation=True
dig=True
tree=False
branch=False
needsFoundation=True
rarity=20
collisionPercentage=10
spawnElevationMin=0
spawnElevationMax=156
spawnInBiome=Custom
[DATA]
0,0,0:17.3
-1,0,1:81
1,0,1:81
0,1,1:81
0,-1,1:81
0,0,1:81
-1,0,2:81
0,0,2:81
0,-1,2:81
1,0,2:81
0,1,2:81
-1,0,3:81
-2,0,3:81
0,-1,3:81
0,-2,3:81
1,0,3:81
2,0,3:81
0,1,3:81
0,2,3:81
0,0,3:81
-1,0,4:81
0,0,4:81
1,0,4:81
0,-1,4:81
0,1,4:81
0,-1,5:81
0,0,5:81
0,1,5:81
-1,0,5:81
1,0,5:81
0,0,6:81
0,0,7:31.2
